Workbook

Sheet Execution Log
A1: TEST EXECUTION LOG
A3: Test Case ID | B3: Module | C3: Priority | D3: Status | E3: Defect ID | F3: Execution Date
A4: TC_LOGIN_001 | B4: Login | C4: High | D4: Pass | F4: 46280
A5: TC_LOGIN_002 | B5: Login | C5: High | D5: Pass | F5: 46280
A6: TC_LOGIN_003 | B6: Login | C6: High | D6: Pass | F6: 46280
A7: TC_LOGIN_004 | B7: Login | C7: High | D7: Pass | F7: 46280
A8: TC_LOGIN_005 | B8: Login | C8: High | D8: Pass | F8: 46280
A9: TC_LOGIN_006 | B9: Login | C9: Low | D9: Pass | F9: 46280
A10: TC_PLP_001 | B10: Product Listing | C10: High | D10: Pass | F10: 46280
A11: TC_PLP_002 | B11: Product Listing | C11: Medium | D11: Pass | F11: 46280
A12: TC_PLP_003 | B12: Product Listing | C12: High | D12: Pass | F12: 46280
A13: TC_PLP_004 | B13: Product Listing | C13: High | D13: Pass | F13: 46280
A14: TC_PLP_005 | B14: Product Listing | C14: Medium | D14: Pass | F14: 46280
A15: TC_PLP_006 | B15: Product Listing | C15: Medium | D15: Fail | E15: DEF-001 | F15: 46280
A16: TC_PDP_001 | B16: Product Details | C16: Medium | D16: Pass | F16: 46280
A17: TC_PDP_002 | B17: Product Details | C17: Medium | D17: Pass | F17: 46280
A18: TC_PDP_003 | B18: Product Details | C18: Low | D18: Pass | F18: 46280
A19: TC_PDP_004 | B19: Product Details | C19: Medium | D19: Pass | F19: 46280
A20: TC_SORT_001 | B20: Sorting | C20: Medium | D20: Pass | F20: 46280
A21: TC_SORT_002 | B21: Sorting | C21: Medium | D21: Pass | F21: 46280
A22: TC_SORT_003 | B22: Sorting | C22: Medium | D22: Pass | F22: 46280
A23: TC_SORT_004 | B23: Sorting | C23: Medium | D23: Pass | F23: 46280
A24: TC_SORT_005 | B24: Sorting | C24: Low | D24: Pass | F24: 46280
A25: TC_CART_001 | B25: Cart | C25: High | D25: Pass | F25: 46280
A26: TC_CART_002 | B26: Cart | C26: High | D26: Pass | F26: 46280
A27: TC_CART_003 | B27: Cart | C27: High | D27: Fail | E27: DEF-004 | F27: 46280
A28: TC_CART_004 | B28: Cart | C28: High | D28: Pass | F28: 46280
A29: TC_CART_005 | B29: Cart | C29: Low | D29: Pass | F29: 46280
A30: TC_CART_006 | B30: Cart | C30: Medium | D30: Pass | F30: 46280
A31: TC_CHECKOUT_001 | B31: Checkout | C31: High | D31: Pass | F31: 46280
A32: TC_CHECKOUT_002 | B32: Checkout | C32: High | D32: Pass | F32: 46280
A33: TC_CHECKOUT_003 | B33: Checkout | C33: High | D33: Pass | F33: 46280
A34: TC_CHECKOUT_004 | B34: Checkout | C34: High | D34: Pass | F34: 46280
A35: TC_CHECKOUT_005 | B35: Checkout | C35: Low | D35: Fail | F35: 46280
A36: TC_CHECKOUT_006 | B36: Checkout | C36: Low | D36: Pass | F36: 46280
A37: TC_CHECKOUT_007 | B37: Checkout | C37: High | D37: Pass | F37: 46280
A38: TC_CHECKOUT_008 | B38: Checkout | C38: Low | D38: Pass | F38: 46280
A39: TC_ORDER_001 | B39: Order Confirmation | C39: High | D39: Pass | F39: 46280
... A43: TC_E2E_002 | B43: End-to-End | C43: High | D43: Pass | F43: 46280
A44: TC_E2E_003 | B44: End-to-End | C44: Medium | D44: Fail | E44: DEF-003 | F44: 46280
...

Sheet Execution Summary
A1: TEST EXECUTION REPORT - E-COMMERCE WEB APPLICATION (SAUCEDEMO)
A3: Cycle | B3: Cycle 1 - Manual Test Execution
A4: Application | B4: SauceDemo (https://www.saucedemo.com)
A5: Executed By | B5: Subham (QA Engineer)
A6: Execution Date | B6: 11-Sep-2026
A8: OVERALL RESULTS
A9: Total Test Cases | B9: =COUNTA('Execution Log'!A4:A48) -> 45
A10: Passed | B10: =COUNTIF('Execution Log'!D4:D48,"Pass") -> 40
A11: Failed | B11: =COUNTIF('Execution Log'!D4:D48,"Fail") -> 5
A12: Blocked / Not Executed | B12: =B9-B10-B11 -> 0
A13: Pass % | B13: =B10/B9 -> 0.88888889
A14: Defects Logged (see Defect_Report.xlsx) | B14: =COUNTIF('Execution Log'!E4:E48,"?*") -> 4
A16: MODULE-WISE BREAKDOWN
A17: Module | B17: Total | C17: Passed | D17: Failed
A18: Login | B18: =COUNTIF('Execution Log'!B4:B48,A18) -> 6 | C18: =COUNTIFS('Execution Log'!B4:B48,A18,'Execution Log'!D4:D48,"Pass") -> 6 | D18: =COUNTIFS('Execution Log'!B4:B48,A18,'Execution Log'!D4:D48,"Fail") -> 0
A19: Product Listing | B19: =COUNTIF('Execution Log'!B4:B48,A19) -> 7 | C19: =COUNTIFS('Execution Log'!B4:B48,A19,'Execution Log'!D4:D48,"Pass") -> 5 | D19: =COUNTIFS('Execution Log'!B4:B48,A19,'Execution Log'!D4:D48,"Fail") -> 2
A20: Product Details | B20: =COUNTIF('Execution Log'!B4:B48,A20) -> 4 | C20: =COUNTIFS('Execution Log'!B4:B48,A20,'Execution Log'!D4:D48,"Pass") -> 4 | D20: =COUNTIFS('Execution Log'!B4:B48,A20,'Execution Log'!D4:D48,"Fail") -> 0
A21: Sorting | B21: =COUNTIF('Execution Log'!B4:B48,A21) -> 5 | C21: =COUNTIFS('Execution Log'!B4:B48,A21,'Execution Log'!D4:D48,"Pass") -> 5 | D21: =COUNTIFS('Execution Log'!B4:B48,A21,'Execution Log'!D4:D48,"Fail") -> 0
A22: Cart | B22: =COUNTIF('Execution Log'!B4:B48,A22) -> 6 | C22: =COUNTIFS('Execution Log'!B4:B48,A22,'Execution Log'!D4:D48,"Pass") -> 5 | D22: =COUNTIFS('Execution Log'!B4:B48,A22,'Execution Log'!D4:D48,"Fail") -> 1
A23: Checkout | B23: =COUNTIF('Execution Log'!B4:B48,A23) -> 8 | C23: =COUNTIFS('Execution Log'!B4:B48,A23,'Execution Log'!D4:D48,"Pass") -> 7 | D23: =COUNTIFS('Execution Log'!B4:B48,A23,'Execution Log'!D4:D48,"Fail") -> 1
A24: Order Confirmation | B24: =COUNTIF('Execution Log'!B4:B48,A24) -> 3 | C24: =COUNTIFS('Execution Log'!B4:B48,A24,'Execution Log'!D4:D48,"Pass") -> 3 | D24: =COUNTIFS('Execution Log'!B4:B48,A24,'Execution Log'!D4:D48,"Fail") -> 0
A25: End-to-End | B25: =COUNTIF('Execution Log'!B4:B48,A25) -> 3 | C25: =COUNTIFS('Execution Log'!B4:B48,A25,'Execution Log'!D4:D48,"Pass") -> 2 | D25: =COUNTIFS('Execution Log'!B4:B48,A25,'Execution Log'!D4:D48,"Fail") -> 1
A26: Session/Logout | B26: =COUNTIF('Execution Log'!B4:B48,A26) -> 3 | C26: =COUNTIFS('Execution Log'!B4:B48,A26,'Execution Log'!D4:D48,"Pass") -> 3 | D26: =COUNTIFS('Execution Log'!B4:B48,A26,'Execution Log'!D4:D48,"Fail") -> 0
